Workbook

Sheet Guidance
A2: Introduction
A3: IGES's GHG emissions database aims to compile the latest information on GHG and CO2 emissions, as reported annually by UNFCCC Annex I countries. The data covers the period from from 1990 up to two years before the submission date of the reports. This database also provides information on target compliance, in order to compare historical emission with countries' emission reduction targets under various regimes.
A4: Table of Contents (links to sheets)
A5: Analytics | D5: Charts are provided to reflect emissions trends over the reported time periods.
A6: GHG & CO2 EMISSIONS | D6: Detailed GHG and CO2 emissions data with and without LULUCF, as reported by UNFCCC Annex 1 countries from 1990 up to the most recent year. The variation over time of those historical emissions for each country is also compared with their emission reduction targets from Nationally Determined Contributions (NDCs) and the Cancun Agreement, in order to evaluate their compliance to the targets so far.
A7: Annex-GHG emissions CP1 | D7: This sheet provides annual emissions, as previously reported until the end of the 1st commitment period (CP1). The methodology that countries used for reporting emissions changed for the 2nd commitment period of the Kyoto Protocol (CP2), therefore emissions over the same period differ slightly in the two sheets. These older emissions data are valuable nonetheless, as they are used as a reference for evaluating compliance to the Kyoto Protocol emission reduction targets, which are shown in this sheet as well.
A8: Update History
A9: Version | B9: Date | C9: Features | F9: Editors
A10: 14 | B10: 45335 | C10: • Update of countries' actual reported emission reductions since 1990 • Update of countries' NDC target | F10: Masatsugu Azuma Machiko Louhisuo
A11: 13.1 | B11: 45231 | C11: • Update of Portugal and Russia | F11: Akibi Tsukui Machiko Louhisuo
A12: 13 | B12: 45078 | C12: • Update of countries' actual reported emission reductions since 1990 • Update of countries' NDC target • Update of GHG emissions from CP1 | F12: Kentaro Takahashi Machiko Louhisuo
A13: 12 | B13: 44713 | C13: • Update of countries' actual reported emission reductions since 1990 • Update of countries' NDC target • Update of GHG emissions from CP1 | F13: Kentaro Takahashi Machiko Louhisuo
A14: 11.1 | B14: 44428 | C14: • Updated region category of UK | F14: Kentaro Takahashi Machiko Louhisuo
A15: 11 | B15: 44408 | C15: • Update of countries' actual reported emission reductions since 1990 • Update of countries' NDC target • Update of GHG emissions from CP1 | F15: Kentaro Takahashi Machiko Louhisuo
A16: 10 | B16: 44031 | C16: • Update of countries' actual reported emission reductions since 1990 • Update of GHG emissions from CP1 | F16: Kentaro Takahashi Machiko Louhisuo
A17: 9.1 | B17: 43800 | C17: • Update of the following countries: Cyprus, Iceland, Kazakhstan, Lithuania, Monaco, Slovakia and Ukraine. | F17: Temuulen Murun Machiko Louhisuo Kentaro Takahashi
A18: 9 | B18: 43617 | C18: • Update of countries' actual reported emission reductions since 1990 • Update of GHG emissions from CP1 • Update of the reference link for the Cancun pledge | F18: Temuulen Murun Machiko Louhisuo Kentaro Takahashi
A19: 8 | B19: 43221 | C19: • Addition of target compliance comparisons, showing the variation between countries' emission reductions target (NDC, Cancun, Kyoto Protocol etc) and their actual reported emission reductions. • Added GHG and CO2 emissions for 2016. • Integrated into one sheet previous four sheets for GHG and CO2 with and without LULUCF • Improved data visualization • Revised guidance sheet • Addition of previously reported emission data from CP1. | F19: Alexis R. Rocamora Machiko Louhisuo Yuji Mizuno
A20: 7.2 | B20: 43009 | C20: Addition of summary charts | F20: Alexis R. Rocamora Yuji Mizuno
A21: 7.1 | B21: 42917 | C21: • Emissions for 2015 have been added. • Emissions for the 1990-2014 period have been updated. • Two new columns for the base year and the percentage of change from base year have been added. • Three new columns have been added, informing on the emissions reductions target of each country under the Cancun Agreement, the respective base year of those targets, and the KP-CP2 emission reductions targets. • Sorting of countries per new categories and alphabetically inside each category. • Update of the guidance sheet, with notably an update history. • Streamlined and more colorful data layout. | F21: Alexis R. Rocamora Yuji Mizuno
... A31: 1 | B31: 40269 | C31: Emissions in 2008 have been added. | F31: N/A
A32: Data Source
A33: Figures for GHG emissions and CO2 emissions in each year are directly extracted from the CRF (Common Reporting Format) of GHG inventory reports submitted by Annex I Parties (https://unfccc.int/ghg-inventories-annex-i-parties/2024) This data is reviewed each year by the ERT so it is subject to change based on the review results. (In fact, it is usual for minor corrections to be carried out at the time of the review). The reported values of GHG emissions based on the Convention and those based on the Kyoto Protocol are deemed to be identical (the abovementioned sinks differ in concept and numerical value). However, France and Denmark, based on inherent extraordinary circumstances, have slight differences in the GHG emissions based on the Convention and GHG emissions based on the Kyoto Protocol. Therefore, this chart deals with those two countries as special cases and shows their emissions based on the Kyoto Protocol. For reference, the emissions reduction targets of each country under the Cancun Agreement and for the second commitment period of the Kyoto Protocol (KP-CP2) are mentioned on the three last columns on the right of the third sheet. Targets under the Cancun agreement can be found here: https://unfccc.int/topics/mitigation/workstreams/pre-2020-ambition/compilation-of-economy-wide-emission-reduction-targets-to-be-implemented-by-parties-included-in-annex-i-to-the-convention Targets for the KP-CP2 are available online here: http://unfccc.int/files/kyoto_protocol/application/pdf/kp_doha_amendment_english.pdf
A34: Disclaimer
A35: Whilst this data is believed to be true and accurate at the date of going to press, neither the editor nor IGES can accept any legal responsibility or liability for any errors or omissions that may have been made. For any queries relating to this database, please contact ce-info@iges.or.jp . All copyrights are reserved. The source must be clearly stated when this database is reproduced or transmitted in any form or by any means.

Sheet Analytics
A1: ANALYTICS
A3: Chart 1: Trend of GHG emissions without LULUCF (1,000 tCO2)
A29: Chart 2: Trend of GHG emissions with LULUCF (1,000 tCO2)
A55: Chart 3: Trend of CO2 emissions without LULUCF (1,000 tCO2)
A81: Chart 4: Trend of CO2 emissions with LULUCF (1,000 tCO2)
A107: Chart 5: Change of GHG emissions without LULUCF from Cancun target base year to latest reported year
A136: Chart 6: Total GHG and CO2 Emissions Trends by all countries

Sheet GHG & CO2 EMISSIONS
E1: GHG & CO2 EMISSIONS (1,000 tCO2) | AL1: Cancun Target Compliance | AO1: Kyoto CP2 Target | AP1: NDC Target Compliance
A2: Region | B2: Party | C2: Emission Type | E2: 1990 | F2: 1991 | G2: 1992 | H2: 1993 | I2: 1994 | J2: 1995 | K2: 1996 | L2: 1997 | M2: 1998 | N2: 1999 | O2: 2000 | P2: 2001 | Q2: 2002 | R2: 2003 | S2: 2004 | T2: 2005 | U2: 2006 | V2: 2007 | W2: 2008 | X2: 2009 | Y2: 2010 | Z2: 2011 | AA2: 2012 | AB2: 2013 | AC2: 2014 | AD2: 2015 | AE2: 2016 | AF2: 2017 | AG2: 2018 | AH2: 2019 | AI2: 2020 | AJ2: 2021 | AK2: 2022 | AL2: Cancun emission reduction target by 2020 | AM2: Cancun target base year | AN2: Change from base to latest reported year | AO2: Kyoto Protocol emission reduction target for CP2 (2013-2020) | AP2: NDC base year | AQ2: NDC emission reduction target | AR2: NDC target year | AS2: Change from base to latest reported year
A3: EU | B3: European Union (excl. UK) | C3: GHG | D3: without LULUCF | E3: 4858721.7 | F3: 4753235.6 | G3: 4602044.3 | H3: 4522014.9 | I3: 4500096.8 | J3: 4550599.9 | K3: 4641592.2 | L3: 4570484.2 | M3: 4531703.7 | N3: 4456534.3 | O3: 4445278.2 | P3: 4494091.8 | Q3: 4480290.9 | R3: 4555586.5 | S3: 4553475.2 | T3: 4536750 | U3: 4540455 | V3: 4491363.9 | W3: 4403507.9 | X3: 4085898.5 | Y3: 4165463.3 | Z3: 4057129.9 | AA3: 3985798.5 | AB3: 3889371 | AC3: 3748899.9 | AD3: 3802730.4 | AE3: 3796348 | AF3: 3818158.2 | AG3: 3739536.2 | AH3: 3573616.1 | AI3: 3282155.2 | AJ3: 3453091.8 | AK3: 3365516.6 | AL3: -20%/30% | AM3: 1990 | AN3: =(AK3/E3)-1 -> -0.30732469 | AO3: -0.2 | AP3: 1990 | AQ3: -0.55 | AR3: 2030 | AS3: =(AK3/E3)-1 -> -0.30732469
D4: with LULUCF | E4: 4641267.6 | F4: 4436277.8 | G4: 4312585.2 | H4: 4218778.8 | I4: 4206188.9 | J4: 4233157 | K4: 4296320.1 | L4: 4232628.5 | M4: 4182882.9 | N4: 4094967.1 | O4: 4134469.1 | P4: 4135616.1 | Q4: 4152573.9 | R4: 4239472.4 | S4: 4200873.7 | T4: 4188474.9 | U4: 4187006.4 | V4: 4187399.5 | W4: 4051126.2 | X4: 3736543.9 | Y4: 3814136.7 | Z4: 3712138 | AA4: 3646351 | AB4: 3541754.7 | AC4: 3417103 | AD4: 3478129.6 | AE4: 3477360.6 | AF4: 3569768.1 | AG4: 3483399.7 | AH4: 3332573.1 | AI4: 3041320.2 | AJ4: 3212146.3 | AK4: 3129062.5 | AN4: =(AK4/E4)-1 -> -0.32581725
C5: CO2 | D5: without LULUCF | E5: 3873023.3 | F5: 3807938.8 | G5: 3681371.1 | H5: 3612170.9 | I5: 3593763.4 | J5: 3640342 | K5: 3725281 | L5: 3659125.5 | M5: 3649833.4 | N5: 3594787 | O5: 3606301.6 | P5: 3663404.2 | Q5: 3664292 | R5: 3743213.4 | S5: 3750816.3 | T5: 3742796.9 | U5: 3759891.2 | V5: 3710709.6 | W5: 3634251.3 | X5: 3339331.7 | Y5: 3432970.3 | Z5: 3335770.6 | AA5: 3266586.5 | AB5: 3177910.4 | AC5: 3042303.3 | AD5: 3101673 | AE5: 3099258 | AF5: 3122783.9 | AG5: 3055340.8 | AH5: 2908385.3 | AI5: 2629904.6 | AJ5: 2808290.9 | AK5: 2740590 | AN5: =(AK5/E5)-1 -> -0.29239001
D6: with LULUCF | E6: 3627466.9 | F6: 3464021.2 | G6: 3365178.1 | H6: 3282183.7 | I6: 3269916.6 | J6: 3293996.2 | K6: 3352484.4 | L6: 3294148.8 | M6: 3273961.3 | N6: 3207405.6 | O6: 3268524.6 | P6: 3279032.5 | Q6: 3311172.3 | R6: 3399845.7 | S6: 3372837.9 | T6: 3368146.2 | U6: 3381141.4 | V6: 3380379.3 | W6: 3257010.1 | X6: 2964679.9 | Y6: 3056367.9 | Z6: 2965654 | AA6: 2901048.7 | AB6: 2805829.8 | AC6: 2686444.1 | AD6: 2752771.5 | AE6: 2755099.2 | AF6: 2846057.5 | AG6: 2774184.9 | AH6: 2642188.1 | AI6: 2363937.6 | AJ6: 2541511.4 | AK6: 2477871.2 | AN6: =(AK6/E6)-1 -> -0.31691419
A7: EU | B7: Austria | C7: GHG | D7: without LULUCF | E7: 79082.673 | F7: 82746.099 | G7: 76176.876 | H7: 76550.864 | I7: 76758.521 | J7: 79985.74 | K7: 83145.349 | L7: 82752.333 | M7: 82045.925 | N7: 80467.643 | O7: 80640.416 | P7: 84524.17 | Q7: 86278.915 | R7: 91647.288 | S7: 91442.942 | T7: 92605.068 | U7: 90193.095 | V7: 87429.937 | W7: 86841.177 | X7: 80222.767 | Y7: 84793.168 | Z7: 82606.721 | AA7: 79889.009 | AB7: 80309.9 | AC7: 76721.305 | AD7: 78934.65 | AE7: 79863.23 | AF7: 82195.35 | AG7: 78903.446 | AH7: 80058.25 | AI7: 74030.056 | AJ7: 77359.765 | AK7: 72844.017 | AL7: -20%/30% | AM7: 1990 | AN7: =(AK7/E7)-1 -> -0.07888778 | AO7: -0.2 | AP7: 1990 | AQ7: -0.55 | AR7: 2030 | AS7: =(AK7/E7)-1 -> -0.07888778
D8: with LULUCF | E8: 67400.869 | F8: 64056.39 | G8: 67151.527 | H8: 59971.959 | I8: 67547.647 | J8: 60651.832 | K8: 64703.305 | L8: 60464.584 | M8: 63159.976 | N8: 60338.767 | O8: 66682.741 | P8: 55422.319 | Q8: 73417.009 | R8: 76663.974 | S8: 69336.475 | T8: 74506.467 | U8: 81440.687 | V8: 82070.255 | W8: 74785.223 | X8: 72484.205 | Y8: 65353.856 | Z8: 67571.663 | AA8: 74445.754 | AB8: 74398.826 | AC8: 69435.655 | AD8: 72700.533 | AE8: 73195.756 | AF8: 79265.473 | AG8: 84125.096 | AH8: 82495.134 | AI8: 68186.605 | AJ8: 66283.801 | AK8: 68370.187 | AN8: =(AK8/E8)-1 -> 0.014381387
C9: CO2 | D9: without LULUCF | E9: 62183.904 | F9: 65782.394 | G9: 60282.904 | H9: 60708.862 | I9: 61083.354 | J9: 64060.755 | K9: 67405.241 | L9: 67301.823 | M9: 66936.726 | N9: 65667.804 | O9: 66177.102 | P9: 70165.582 | Q9: 71969.395 | R9: 77396.065 | S9: 77693.557 | T9: 79091.841 | U9: 76811.652 | V9: 74112.26 | W9: 73489.915 | X9: 67306.605 | Y9: 72008.308 | Z9: 69901.455 | AA9: 67274.365 | AB9: 67766.779 | AC9: 64165.827 | AD9: 66357.461 | AE9: 67217.282 | AF9: 69598.48 | AG9: 66561.692 | AH9: 67945.995 | AI9: 62175.724 | AJ9: 65757.468 | AK9: 61489.111 | AN9: =(AK9/E9)-1 -> -0.011173184
D10: with LULUCF | E10: 50331.835 | F10: 46920.505 | G10: 51082.471 | H10: 43952.363 | I10: 51697.111 | J10: 44554.599 | K10: 48794.883 | L10: 44849.722 | M10: 47889.495 | N10: 45379.382 | O10: 52060.778 | P10: 40904.818 | Q10: 58947.6 | R10: 62252.148 | S10: 55427.401 | T10: 60833.115 | U10: 67898.247 | V10: 68591.137 | W10: 61270.067 | X10: 59402.92 | Y10: 52404.03 | Z10: 54702.059 | AA10: 61666.938 | AB10: 61693.008 | AC10: 56719.505 | AD10: 59962.485 | AE10: 60389.386 | AF10: 66508.183 | AG10: 71624.286 | AH10: 70225.321 | AI10: 56176.191 | AJ10: 54526.379 | AK10: 56860.452 | AN10: =(AK10/E10)-1 -> 0.12971148
A11: EU | B11: Belgium | C11: GHG | D11: without LULUCF | E11: 145849.07 | F11: 148583.67 | G11: 148081.78 | H11: 146900.46 | I11: 151448.74 | J11: 153582.79 | K11: 157230.45 | L11: 148822.76 | M11: 154014.78 | N11: 147734.61 | O11: 148878.6 | P11: 147319.84 | Q11: 147415.86 | R11: 147731.91 | S11: 148534.7 | T11: 145429.61 | U11: 142727.88 | V11: 139108.26 | W11: 139040.34 | X11: 126454.25 | Y11: 133528.53 | Z11: 123219.08 | AA11: 120467.91 | AB11: 120564.33 | AC11: 114873 | AD11: 119108.08 | AE11: 117528.19 | AF11: 117035.08 | AG11: 117769.67 | AH11: 116679.93 | AI11: 107420.53 | AJ11: 110195.86 | AK11: 103576.13 | AL11: -20%/30% | AM11: 1990 | AN11: =(AK11/E11)-1 -> -0.28984036 | AO11: -0.2 | AP11: 1990 | AQ11: -0.55 | AR11: 2030 | AS11: =(AK11/E11)-1 -> -0.28984036
D12: with LULUCF | E12: 142909.17 | F12: 146108.91 | G12: 145787.05 | H12: 144588.62 | I12: 149388.05 | J12: 151293.63 | K12: 154745.21 | L12: 146787.6 | M12: 151423.19 | N12: 145618.48 | O12: 147183.36 | P12: 145795.82 | Q12: 145299.95 | R12: 145721.36 | S12: 146819.66 | T12: 143654.77 | U12: 140976.15 | V12: 137658.11 | W12: 137663.9 | X12: 125250.66 | Y12: 133168.91 | Z12: 122964.12 | AA12: 120229.4 | AB12: 119786.69 | AC12: 114081.91 | AD12: 118366.96 | AE12: 116855.59 | AF12: 116479.46 | AG12: 117203.08 | AH12: 116268.33 | AI12: 107035.81 | AJ12: 109915.24 | AK12: 103157.14 | AN12: =(AK12/E12)-1 -> -0.27816292
C13: CO2 | D13: without LULUCF | E13: 120297.34 | F13: 123366.65 | G13: 122492.46 | H13: 121427.34 | I13: 124800 | J13: 125939.2 | K13: 129481.18 | L13: 123992.66 | M13: 130225.32 | N13: 124682.83 | O13: 126723.04 | P13: 126066.95 | Q13: 126863.56 | R13: 128248.59 | S13: 128781.74 | T13: 125639.61 | U13: 123884.25 | V13: 120481.2 | W13: 120179.66 | X13: 107780.14 | Y13: 114489.6 | Z13: 105097.98 | AA13: 102434.54 | AB13: 102761.55 | AC13: 97033.593 | AD13: 101275.02 | AE13: 99741.557 | AF13: 99192.034 | AG13: 100158.57 | AH13: 99684.187 | AI13: 91228.272 | AJ13: 94886.097 | AK13: 89002.058 | AN13: =(AK13/E13)-1 -> -0.26014941
D14: with LULUCF | E14: 117351.91 | F14: 120883.3 | G14: 120186.09 | H14: 119100.76 | I14: 122721.54 | J14: 123629.36 | K14: 126962.36 | L14: 121930.58 | M14: 127603.67 | N14: 122533.68 | O14: 124991.72 | P14: 124503.75 | Q14: 124705.3 | R14: 126192.63 | S14: 126997.8 | T14: 123792.92 | U14: 122057.75 | V14: 118953.34 | W14: 118722.59 | X14: 106493.02 | Y14: 114044.07 | Z14: 104751.6 | AA14: 102105.41 | AB14: 101893.17 | AC14: 96151.672 | AD14: 100442.99 | AE14: 98976.863 | AF14: 98543.167 | AG14: 99497.528 | AH14: 99176.914 | AI14: 90746.704 | AJ14: 94506.902 | AK14: 88483.891 | AN14: =(AK14/E14)-1 -> -0.24599533
A15: EU | B15: Bulgaria | C15: GHG | D15: without LULUCF | E15: 98800.788 | F15: 80943.322 | G15: 75410.631 | H15: 74721.423 | I15: 70653.014 | J15: 72207.971 | K15: 72647.461 | L15: 69433.501 | M15: 65390.218 | N15: 58356.483 | O15: 57511.92 | P15: 60401.552 | Q15: 57797.613 | R15: 62694.771 | S15: 61817.254 | T15: 62347.443 | U15: 63104.636 | V15: 66950.197 | W15: 65611.709 | X15: 56719.076 | Y15: 59363.946 | Z15: 64746.442 | AA15: 59673.445 | AB15: 54313.585 | AC15: 57270.218 | AD15: 60450.684 | AE15: 57802.317 | AF15: 59607.944 | AG15: 55252.884 | AH15: 53942.89 | AI15: 47963.35 | AJ15: 54030.656 | AK15: 58420.851 | AL15: -20%/30% | AM15: 1990 | AN15: =(AK15/E15)-1 -> -0.40870056 | AO15: -0.2 | AP15: 1990 | AQ15: -0.55 | AR15: 2030 | AS15: =(AK15/E15)-1 -> -0.40870056
D16: with LULUCF | E16: 81023.164 | F16: 63198.306 | G16: 58244.555 | H16: 57341.113 | I16: 53260.6 | J16: 54813.904 | K16: 55976.903 | L16: 52646.613 | M16: 48963.81 | N16: 42142.867 | O16: 40169.967 | P16: 45796.24 | Q16: 42938.82 | R16: 48276.83 | S16: 46721.902 | T16: 46052.856 | U16: 50084.494 | V16: 53035.394 | W16: 53281.637 | X16: 44246.689 | Y16: 47426.873 | Z16: 56099.166 | AA16: 51469.262 | AB16: 47121.249 | AC16: 48815.108 | AD16: 52446.606 | AE16: 48007.878 | AF16: 49827.041 | AG16: 45380.907 | AH16: 44356.946 | AI16: 38357.875 | AJ16: 44451.734 | AK16: 48880.816 | AN16: =(AK16/E16)-1 -> -0.39670566
C17: CO2 | D17: without LULUCF | E17: 76520.385 | F17: 61534.54 | G17: 57369.195 | H17: 58399.537 | I17: 56392.825 | J17: 57926.709 | K17: 58470.427 | L17: 55819.149 | M17: 53126.685 | N17: 46378.916 | O17: 45516.045 | P17: 49034.393 | Q17: 46155.216 | R17: 50504.308 | S17: 49542.805 | T17: 50605.6 | U17: 51843.668 | V17: 55674.04 | W17: 54033.684 | X17: 45761.529 | Y17: 47826.461 | Z17: 53131.781 | AA17: 48288.869 | AB17: 42652.178 | AC17: 45178.741 | AD17: 48131.472 | AE17: 45345.743 | AF17: 47447.219 | AG17: 43508.753 | AH17: 42199.323 | AI17: 36583.958 | AJ17: 42357.014 | AK17: 46931.015 | AN17: =(AK17/E17)-1 -> -0.38668611
D18: with LULUCF | E18: 58675.191 | F18: 43726.407 | G18: 40123.747 | H18: 40891.288 | I18: 38875.452 | J18: 40479.424 | K18: 41742.35 | L18: 38982.154 | M18: 36627.542 | N18: 30083.766 | O18: 27896.902 | P18: 34303.3 | Q18: 31226.243 | R18: 36023.006 | S18: 34400.981 | T18: 34263.625 | U18: 38767.279 | V18: 41545.064 | W18: 41636.501 | X18: 33232.814 | Y18: 35807.135 | Z18: 44392.285 | AA18: 39958.801 | AB18: 35351.775 | AC18: 36625.274 | AD18: 40006.81 | AE18: 35428.056 | AF18: 37550.683 | AG18: 33534.413 | AH18: 32499.95 | AI18: 26865.543 | AJ18: 32672.892 | AK18: 37266.3 | AN18: =(AK18/E18)-1 -> -0.36487126
A19: EU | B19: Croatia | C19: GHG | D19: without LULUCF | E19: 31546.32 | F19: 25021.258 | G19: 23134.505 | H19: 23122.502 | I19: 22206.748 | J19: 22875.232 | K19: 23366.34 | L19: 24748.203 | M19: 24885.897 | N19: 26204.315 | O19: 25826.808 | P19: 27007.33 | Q19: 28100.999 | R19: 29537.889 | S19: 29497.65 | T19: 29962.839 | U19: 30356.468 | V19: 31781.252 | W19: 30828.118 | X19: 28677.704 | Y19: 28289.566 | Z19: 28002.01 | AA19: 26265.917 | AB19: 25044.74 | AC19: 24312.757 | AD19: 24770.42 | AE19: 24942.282 | AF19: 25785.316 | AG19: 24659.626 | AH19: 24830.697 | AI19: 23914.495 | AJ19: 24437.179 | AK19: 24551.983 | AL19: -0.05 | AM19: 1990 | AN19: =(AK19/E19)-1 -> -0.22171642 | AO19: -0.2 | AP19: 1990 | AQ19: -0.55 | AR19: 2030 | AS19: =(AK19/E19)-1 -> -0.22171642
D20: with LULUCF | E20: 25198.284 | F20: 17493.624 | G20: 15506.44 | H20: 15327.036 | I20: 14143.556 | J20: 14324.07 | K20: 15171.313 | L20: 17164.872 | M20: 17494.855 | N20: 18019.172 | O20: 19088.672 | P20: 19025.881 | Q20: 19837.629 | R20: 22101.028 | S20: 21731.483 | T20: 21959.589 | U20: 22539.683 | V20: 25118.269 | W20: 23962.791 | X20: 21706.301 | Y20: 21382.737 | Z20: 22374.768 | AA20: 21080.048 | AB20: 18894.229 | AC20: 18310.035 | AD20: 19078.518 | AE20: 19244.073 | AF20: 20901.631 | AG20: 19166.842 | AH20: 19104.851 | AI20: 18255.881 | AJ20: 18673.449 | AK20: 19684.823 | AN20: =(AK20/E20)-1 -> -0.21880306
C21: CO2 | D21: without LULUCF | E21: 22874.491 | F21: 16992.687 | G21: 16374.967 | H21: 16807.773 | I21: 16051.528 | J21: 16811.348 | K21: 17335.912 | L21: 18566.835 | M21: 19038.723 | N21: 20081.425 | O21: 19652.269 | P21: 20776.024 | Q21: 21916.044 | R21: 23227.37 | S21: 22854.53 | T21: 23297.976 | U21: 23499.119 | V21: 24804.672 | W21: 23520.155 | X21: 21756.484 | Y21: 20986.248 | Z21: 20620.634 | AA21: 19056.3 | AB21: 18406.078 | AC21: 17657.192 | AD21: 17803.005 | AE21: 18089.979 | AF21: 18719.1 | AG21: 17702.566 | AH21: 17830.287 | AI21: 16881.603 | AJ21: 17410.67 | AK21: 17608.212 | AN21: =(AK21/E21)-1 -> -0.23022499
D22: with LULUCF | E22: 16480.416 | F22: 9416.0547 | G22: 8677.4106 | H22: 8910.2902 | I22: 7926.0489 | J22: 8205.1618 | K22: 9070.539 | L22: 10911.736 | M22: 11527.91 | N22: 11845.115 | O22: 12705.011 | P22: 12714.222 | Q22: 13587.811 | R22: 15661.11 | S22: 15015.42 | T22: 15213.541 | U22: 15586.881 | V22: 17991.421 | W22: 16534.07 | X22: 14661.556 | Y22: 13950.642 | Z22: 14822.378 | AA22: 13653.652 | AB22: 12098.841 | AC22: 11495.891 | AD22: 11925.32 | AE22: 12214.598 | AF22: 13551.106 | AG22: 12043.789 | AH22: 11936.022 | AI22: 11002.74 | AJ22: 11480.244 | AK22: 12534.154 | AN22: =(AK22/E22)-1 -> -0.2394516
A23: EU | B23: Cyprus | C23: GHG | D23: without LULUCF | E23: 5570.3489 | F23: 6074.8994 | G23: 6511.3843 | H23: 6798.5807 | I23: 7055.1086 | J23: 6970.5207 | K23: 7343.524 | L23: 7437.6235 | M23: 7753.5128 | N23: 8031.5696 | O23: 8303.5193 | P23: 8244.7577 | Q23: 8480.4362 | R23: 8871.5459 | S23: 9077.7558 | T23: 9226.0111 | U23: 9473.0052 | V23: 9807.7678 | W23: 10031.229 | X23: 9795.9268 | Y23: 9460.2333 | Z23: 9162.6109 | AA23: 8628.5145 | AB23: 7921.4316 | AC23: 8295.6797 | AD23: 8343.8455 | AE23: 8772.2033 | AF23: 8939.6482 | AG23: 8837.9802 | AH23: 8889.0158 | AI23: 8514.7921 | AJ23: 8717.5471 | AK23: 8772.2938 | AL23: -20%/30% | AM23: 1990 | AN23: =(AK23/E23)-1 -> 0.57481944 | AO23: -0.2 | AP23: 1990 | AQ23: -0.55 | AR23: 2030 | AS23: =(AK23/E23)-1 -> 0.57481944
D24: with LULUCF | E24: 5417.2799 | F24: 5907.9125 | G24: 6338.7298 | H24: 6623.7684 | I24: 6871.7492 | J24: 6790.4752 | K24: 7158.1533 | L24: 7253.3931 | M24: 7563.005 | N24: 7833.1743 | O24: 8160.9938 | P24: 8076.1377 | Q24: 8278.4717 | R24: 8657.4943 | S24: 8863.1685 | T24: 9005.1413 | U24: 9250.4708 | V24: 9624.8328 | W24: 9781.3436 | X24: 9518.2265 | Y24: 9195.1504 | Z24: 8861.7881 | AA24: 8334.85 | AB24: 7624.106 | AC24: 7996.532 | AD24: 8047.7011 | AE24: 8581.274 | AF24: 8632.5814 | AG24: 8535.6346 | AH24: 8591.9417 | AI24: 8216.2163 | AJ24: 8482.1927 | AK24: 8472.8797 | AN24: =(AK24/E24)-1 -> 0.56404687
C25: CO2 | D25: without LULUCF | E25: 4645.473 | F25: 5133.5712 | G25: 5506.0796 | H25: 5749.7073 | I25: 5991.909 | J25: 5862.4034 | K25: 6212.3458 | L25: 6298.7451 | M25: 6592.9381 | N25: 6859.5131 | O25: 7102.9565 | P25: 6976.4838 | Q25: 7167.9227 | R25: 7557.6087 | S25: 7787.5091 | T25: 7959.3863 | U25: 8186.4592 | V25: 8505.3459 | W25: 8718.0746 | X25: 8474.9482 | Y25: 8104.2256 | Z25: 7790.62 | AA25: 7264.8829 | AB25: 6584.1731 | AC25: 6952.6013 | AD25: 6974.856 | AE25: 7357.9013 | AF25: 7479.3229 | AG25: 7341.7729 | AH25: 7345.3809 | AI25: 6925.6572 | AJ25: 7081.4458 | AK25: 7118.3932 | AN25: =(AK25/E25)-1 -> 0.53232905
D26: with LULUCF | E26: 4492.3443 | F26: 4966.4121 | G26: 5333.3469 | H26: 5574.468 | I26: 5807.5025 | J26: 5681.909 | K26: 6026.256 | L26: 6113.5025 | M26: 6399.1703 | N26: 6661.0004 | O26: 6953.5133 | P26: 6805.3224 | Q26: 6965.5073 | R26: 7342.7422 | S26: 7571.6916 | T26: 7737.5253 | U26: 7962.5004 | V26: 8316.7374 | W26: 8467.0055 | X26: 8195.9122 | Y26: 7836.952 | Z26: 7487.7553 | AA26: 6969.0346 | AB26: 6285.3415 | AC26: 6651.9017 | AD26: 6677.4224 | AE26: 7153.7297 | AF26: 7170.7259 | AG26: 7037.5278 | AH26: 7046.624 | AI26: 6625.2872 | AJ26: 6836.7229 | AK26: 6817.6615 | AN26: =(AK26/E26)-1 -> 0.51761778
A27: EU | B27: Czech Republic | C27: GHG | D27: without LULUCF | E27: 199386.71 | F27: 180862.33 | G27: 174988.44 | H27: 168156.55 | I27: 159400.88 | J27: 158415.84 | K27: 161630.92 | L27: 157199.21 | M27: 151181.59 | N27: 141096.08 | O27: 151386.04 | P27: 151141.41 | Q27: 147318.94 | R27: 150425 | S27: 151420.98 | T27: 149308.22 | U27: 150630.09 | V27: 152380.68 | W27: 147309.58 | X27: 137590.05 | Y27: 140529.12 | Z27: 139120.13 | AA27: 135193.43 | AB27: 129792.72 | AC27: 127583.16 | AD27: 129240.89 | AE27: 130796.98 | AF27: 131636.87 | AG27: 129789 | AH27: 123933.44 | AI27: 113392.76 | AJ27: 118776.42 | AK27: 117076.83 | AL27: -20%/30% | AM27: 1990 | AN27: =(AK27/E27)-1 -> -0.41281527 | AO27: -0.2 | AP27: 1990 | AQ27: -0.55 | AR27: 2030 | AS27: =(AK27/E27)-1 -> -0.41281527
D28: with LULUCF | E28: 190549.6 | F28: 170524.55 | G28: 164454.15 | H28: 156792.4 | I28: 149283.05 | J28: 148033.05 | K28: 151525.69 | L28: 148135.57 | M28: 142462.17 | N28: 132156.44 | O28: 141701.06 | P28: 141484.95 | Q28: 137868.28 | R28: 141474.56 | S28: 142756.34 | T28: 140585.45 | U28: 142964.45 | V28: 144948.91 | W28: 138625.93 | X28: 129151.89 | Y28: 132816.62 | Z28: 130785.73 | AA28: 126636.7 | AB28: 121882.22 | AC28: 119730.65 | AD28: 121386.24 | AE28: 123850.17 | AF28: 126297.98 | AG28: 129776.84 | AH28: 130426.32 | AI28: 123091.99 | AJ28: 125363.89 | AK28: 120454.38 | AN28: =(AK28/E28)-1 -> -0.36785813
C29: CO2 | D29: without LULUCF | E29: 164250.45 | F29: 148883.28 | G29: 145705.82 | H29: 140124.1 | I29: 132668.12 | J29: 131622.32 | K29: 135018.76 | L29: 130941.74 | M29: 125715.92 | N29: 116672.03 | O29: 127236.14 | P29: 127144.52 | Q29: 123967.85 | R29: 127571.89 | S29: 128291.81 | T29: 125690.86 | U29: 126537.1 | V29: 128366.4 | W29: 122934.9 | X29: 114982.54 | Y29: 117476.26 | Z29: 115189.18 | AA29: 111287.35 | AB29: 106722.49 | AC29: 104246.04 | AD29: 105000.92 | AE29: 106648.4 | AF29: 107745.84 | AG29: 106335.55 | AH29: 101008.82 | AI29: 91673.765 | AJ29: 96645.177 | AK29: 95107.761 | AN29: =(AK29/E29)-1 -> -0.42095891
D30: with LULUCF | E30: 155375.92 | F30: 138516.72 | G30: 135131.2 | H30: 128716.62 | I30: 122509.67 | J30: 121205.82 | K30: 124859.88 | L30: 121807.29 | M30: 116953.11 | N30: 107699.74 | O30: 117520.08 | P30: 117470.98 | Q30: 114498.26 | R30: 118586.39 | S30: 119604.45 | T30: 116947.36 | U30: 118845.36 | V30: 120905.72 | W30: 114229.61 | X30: 106523.76 | Y30: 109741.89 | Z30: 106843.21 | AA30: 102714.53 | AB30: 98803.886 | AC30: 96378.889 | AD30: 97133.994 | AE30: 99692.171 | AF30: 102396.89 | AG30: 106307.97 | AH30: 107483.95 | AI30: 101355.07 | AJ30: 103217.44 | AK30: 98451.812 | AN30: =(AK30/E30)-1 -> -0.36636378
A31: EU | B31: Denmark | C31: GHG | D31: without LULUCF | E31: 70388.1 | F31: 81068.884 | G31: 75197.426 | H31: 77548.913 | I31: 81509.518 | J31: 78647.254 | K31: 91731.139 | L31: 82216.861 | M31: 78273.362 | N31: 75607.301 | O31: 71308.324 | P31: 72889.598 | Q31: 72436.564 | R31: 77428.792 | S31: 71492.906 | T31: 67172.285 | U31: 74878.998 | V31: 70223.861 | W31: 66662.861 | X31: 63933.022 | Y31: 64127.007 | Z31: 58950.642 | AA31: 54416.175 | AB31: 56144.292 | AC31: 51973.814 | AD31: 49255.935 | AE31: 51274.642 | AF31: 48960.464 | AG31: 48800.854 | AH31: 44907.452 | AI31: 42252.285 | AJ31: 43245.692 | AK31: 41769.353 | AL31: -20%/30% | AM31: 1990 | AN31: =(AK31/E31)-1 -> -0.40658503 | AO31: -0.2 | AP31: 1990 | AQ31: -0.55 | AR31: 2030 | AS31: =(AK31/E31)-1 -> -0.40658503
D32: with LULUCF | E32: 77082.068 | F32: 87096.227 | G32: 82132.957 | H32: 83162.638 | I32: 86646.496 | J32: 83964.582 | K32: 96334.505 | L32: 87294.118 | M32: 83266.834 | N32: 80912.268 | O32: 76395.625 | P32: 77465.888 | Q32: 78081.107 | R32: 82830.866 | S32: 76695.925 | T32: 72143.131 | U32: 80303.928 | V32: 75819.224 | W32: 70761.919 | X32: 67315.339 | Y32: 66487.652 | Z32: 60554.844 | AA32: 55405.616 | AB32: 56817.21 | AC32: 52863.07 | AD32: 49161.097 | AE32: 52142.42 | AF32: 49675.67 | AG32: 51303.589 | AH32: 46438.417 | AI32: 43544.643 | AJ32: 43444.177 | AK32: 41388.363 | AN32: =(AK32/E32)-1 -> -0.46306107
C33: CO2 | D33: without LULUCF | E33: 53369.625 | F33: 63985.358 | G33: 58200.779 | H33: 60463.097 | I33: 64546.721 | J33: 61530.136 | K33: 74763.086 | L33: 65314.343 | M33: 61122.953 | N33: 58539.647 | O33: 54194.545 | P33: 55795.432 | Q33: 55458.774 | R33: 60555.632 | S33: 55013.952 | T33: 51449.767 | U33: 59420.571 | V33: 54631.081 | W33: 51174.755 | X33: 48774.674 | Y33: 49116.938 | Z33: 44161.926 | AA33: 39789.048 | AB33: 41684.68 | AC33: 37504.934 | AD33: 35039.321 | AE33: 36848.061 | AF33: 34597.194 | AG33: 34540.957 | AH33: 30883.842 | AI33: 28224.367 | AJ33: 29516.037 | AK33: 28371.274 | AN33: =(AK33/E33)-1 -> -0.46840035
D34: with LULUCF | E34: 59701.706 | F34: 69652.735 | G34: 64777.133 | H34: 65718.418 | I34: 69326.049 | J34: 66492.531 | K34: 79014.199 | L34: 70041.98 | M34: 65769.357 | N34: 63500.144 | O34: 58939.889 | P34: 60032.222 | Q34: 60766.234 | R34: 65623.02 | S34: 59883.488 | T34: 56086.956 | U34: 64509.716 | V34: 59888.54 | W34: 54933.754 | X34: 51814.776 | Y34: 51135.393 | Z34: 45427.673 | AA34: 40443.227 | AB34: 42027.664 | AC34: 38067.612 | AD34: 34620.037 | AE34: 37387.301 | AF34: 34983.861 | AG34: 36717.184 | AH34: 32082.366 | AI34: 29177.717 | AJ34: 29370.805 | AK34: 27640.396 | AN34: =(AK34/E34)-1 -> -0.53702501
A35: EU | B35: Estonia | C35: GHG | D35: without LULUCF | E35: 40273.576 | F35: 37398.494 | G35: 27212.186 | H35: 21747.878 | I35: 22220.199 | J35: 20057.12 | K35: 20998.018 | L35: 20708.904 | M35: 18983.758 | N35: 17820.07 | O35: 17441.798 | P35: 17875.078 | Q35: 17287.029 | R35: 19219.739 | S35: 19356.25 | T35: 19132.889 | U35: 18478.015 | V35: 22029.264 | W35: 19930.143 | X35: 16494.962 | Y35: 21096.262 | Z35: 21053.638 | AA35: 19941.947 | AB35: 21819.402 | AC35: 20981.392 | AD35: 17913.77 | AE35: 19533.129 | AF35: 20761.227 | AG35: 19950.295 | AH35: 14508.113 | AI35: 11343.379 | AJ35: 12578.984 | AK35: 13951.546 | AL35: -20%/30% | AM35: 1990 | AN35: =(AK35/E35)-1 -> -0.65358065 | AO35: -0.2 | AP35: 1990 | AQ35: -0.55 | AR35: 2030 | AS35: =(AK35/E35)-1 -> -0.65358065
D36: with LULUCF | E36: 35038.308 | F36: 32310.208 | G36: 22903.69 | H36: 16554.893 | I36: 17429.474 | J36: 15093.443 | K36: 15737.521 | L36: 15321.53 | M36: 14086.726 | N36: 14021.843 | O36: 13972.13 | P36: 15031.154 | Q36: 15519.6 | R36: 18242.386 | S36: 17749.022 | T36: 16205.614 | U36: 14466.452 | V36: 16674.441 | W36: 14377.951 | X36: 10173.245 | Y36: 16426.784 | Z36: 17885.216 | AA36: 18394.048 | AB36: 21375.769 | AC36: 21333.565 | AD36: 18811.831 | AE36: 21439.736 | AF36: 22529.322 | AG36: 23421.051 | AH36: 17787.142 | AI36: 12586.283 | AJ36: 13390.501 | AK36: 14290.838 | AN36: =(AK36/E36)-1 -> -0.59213675
C37: CO2 | D37: without LULUCF | E37: 36916.964 | F37: 34144.173 | G37: 24417.833 | H37: 19435.266 | I37: 20040.797 | J37: 18054.97 | K37: 19033.944 | L37: 18673.174 | M37: 16933.062 | N37: 15929.464 | O37: 15470.923 | P37: 15869.869 | Q37: 15357.951 | R37: 17250.687 | S37: 17322.094 | T37: 17089.781 | U37: 16438.181 | V37: 19930.493 | W37: 17814.806 | X37: 14404.983 | Y37: 18964.735 | Z37: 18948.026 | AA37: 17761.414 | AB37: 19633.824 | AC37: 18783.953 | AD37: 15779.623 | AE37: 17432.914 | AF37: 18616.033 | AG37: 17800.686 | AH37: 12288.099 | AI37: 9198.2509 | AJ37: 10390.745 | AK37: 11757.177 | AN37: =(AK37/E37)-1 -> -0.68152372
D38: with LULUCF | E38: 31371.222 | F38: 28745.488 | G38: 19795.613 | H38: 13930.234 | I38: 14937.956 | J38: 12779.241 | K38: 13460.258 | L38: 12971.171 | M38: 11723.036 | N38: 11816.59 | O38: 11685.612 | P38: 12710.997 | Q38: 13271.562 | R38: 15956.521 | S38: 15396.704 | T38: 13843.878 | U38: 12098.55 | V38: 14253.516 | W38: 11937.513 | X38: 7757.3604 | Y38: 13967.979 | Z38: 15451.235 | AA38: 15883.824 | AB38: 18859.235 | AC38: 18803.688 | AD38: 16343.199 | AE38: 19003.212 | AF38: 20047.107 | AG38: 20929.897 | AH38: 15227.492 | AI38: 10100.156 | AJ38: 10860.947 | AK38: 11754.774 | AN38: =(AK38/E38)-1 -> -0.62530073
A39: EU | B39: Finland | C39: GHG | D39: without LULUCF | E39: 71165.925 | F39: 69092.868 | G39: 67721.271 | H39: 69936.172 | I39: 75505.773 | J39: 71758.493 | K39: 77763.643 | L39: 76423.372 | M39: 72733.204 | N39: 72052.851 | O39: 70112.916 | P39: 75430.123 | Q39: 77838.05 | R39: 85424.042 | S39: 81663.008 | T39: 69625.546 | U39: 80996.713 | V39: 79324.558 | W39: 71180.613 | X39: 67558.99 | Y39: 75399.643 | Z39: 67653.3 | AA39: 62114.798 | AB39: 62585.654 | AC39: 58404.494 | AD39: 54904.747 | AE39: 57753.672 | AF39: 54947.573 | AG39: 55878.672 | AH39: 52591.179 | AI39: 47586.769 | AJ39: 47545.903 | AK39: 45648.909 | AL39: -20%/30% | AM39: 1990 | AN39: =(AK39/E39)-1 -> -0.35855665 | AO39: -0.2 | AP39: 1990 | AQ39: -0.55 | AR39: 2030 | AS39: =(AK39/E39)-1 -> -0.35855665
D40: with LULUCF | E40: 47991.06 | F40: 33512.921 | G40: 38174.441 | H40: 39752.128 | I40: 52135.301 | J40: 49758.012 | K40: 49456.702 | L40: 52763.929 | M40: 51139.464 | N40: 50286.33 | O40: 48855.147 | P40: 53554.159 | Q40: 54889.248 | R40: 62057.63 | S40: 56874.621 | T40: 44775.18 | U40: 52249.176 | V40: 60223.648 | W40: 49498.858 | X40: 33652.657 | Y40: 53021.475 | Z40: 46033.171 | AA40: 38773.076 | AB40: 46028.858 | AC40: 40863.09 | AD40: 41773.671 | AE40: 48261.004 | AF40: 47916.065 | AG40: 58203.15 | AH40: 49357.934 | AI40: 42232.464 | AJ40: 51020.144 | AK40: 50091.891 | AN40: =(AK40/E40)-1 -> 0.043775483
...

Sheet Annex-GHG emissions CP1
C1: Reference emissions | F1: GHG Emissions without LULUCF reported for the first commitment period of the Kyoto Protocol | AC1: Kyoto Target Compliance
A2: Region | B2: Party | C2: Base year emissions | D2: Assigned emissions for CP1 (2008-2012) | E2: Annual assigned emissions for CP1 | F2: 1990 | G2: 1991 | H2: 1992 | I2: 1993 | J2: 1994 | K2: 1995 | L2: 1996 | M2: 1997 | N2: 1998 | O2: 1999 | P2: 2000 | Q2: 2001 | R2: 2002 | S2: 2003 | T2: 2004 | U2: 2005 | V2: 2006 | W2: 2007 | X2: 2008 | Y2: 2009 | Z2: 2010 | AA2: 2011 | AB2: 2012 | AC2: Kyoto Protocol target | AD2: Average CP1 emissions (2008-2012) | AE2: Change from base year emissions to average CP1 emissions
A3: EU14 | B3: European Union (14) | C3: 3485613.7 | D3: 16209301 | E3: =D3/5 -> 3241860.3 | F3: ='GHG & CO2 EMISSIONS'!E3 -> 4858721.7 | G3: ='GHG & CO2 EMISSIONS'!F3 -> 4753235.6 | H3: ='GHG & CO2 EMISSIONS'!G3 -> 4602044.3 | I3: ='GHG & CO2 EMISSIONS'!H3 -> 4522014.9 | J3: ='GHG & CO2 EMISSIONS'!I3 -> 4500096.8 | K3: ='GHG & CO2 EMISSIONS'!J3 -> 4550599.9 | L3: ='GHG & CO2 EMISSIONS'!K3 -> 4641592.2 | M3: ='GHG & CO2 EMISSIONS'!L3 -> 4570484.2 | ... AB3: ='GHG & CO2 EMISSIONS'!AA3 -> 3985798.5 | AC3: -0.08 | AD3: =AVERAGE(X3:AB3) -> 4139559.6 | AE3: =(AD3/C3)-1 -> 0.18761286
A4: EU14 | B4: Germany | C4: 1232429.5 | D4: 4868096.7 | E4: =D4/5 -> 973619.34 | F4: ='GHG & CO2 EMISSIONS'!E47 -> 1250658.1 | G4: ='GHG & CO2 EMISSIONS'!F47 -> 1204651.7 | H4: ='GHG & CO2 EMISSIONS'!G47 -> 1155057.6 | I4: ='GHG & CO2 EMISSIONS'!H47 -> 1145879.3 | J4: ='GHG & CO2 EMISSIONS'!I47 -> 1127753.9 | K4: ='GHG & CO2 EMISSIONS'!J47 -> 1120598.2 | L4: ='GHG & CO2 EMISSIONS'!K47 -> 1137857.9 | M4: ='GHG & CO2 EMISSIONS'!L47 -> 1102105.2 | ... AB4: ='GHG & CO2 EMISSIONS'!AA47 -> 914497.84 | AC4: -0.21 | AD4: =AVERAGE(X4:AB4) -> 923024.35 | AE4: =(AD4/C4)-1 -> -0.25105305
A5: EU14 | B5: France | C5: 563925.33 | D5: 2819626.6 | E5: =D5/5 -> 563925.33 | F5: ='GHG & CO2 EMISSIONS'!E43 -> 537837.22 | G5: ='GHG & CO2 EMISSIONS'!F43 -> 563578.37 | H5: ='GHG & CO2 EMISSIONS'!G43 -> 553277.05 | I5: ='GHG & CO2 EMISSIONS'!H43 -> 531812.54 | J5: ='GHG & CO2 EMISSIONS'!I43 -> 523549.45 | K5: ='GHG & CO2 EMISSIONS'!J43 -> 529460.52 | L5: ='GHG & CO2 EMISSIONS'!K43 -> 547709.94 | M5: ='GHG & CO2 EMISSIONS'!L43 -> 539953.86 | ... AB5: ='GHG & CO2 EMISSIONS'!AA43 -> 482021.79 | AC5: 0 | AD5: =AVERAGE(X5:AB5) -> 498344.17 | AE5: =(AD5/C5)-1 -> -0.11629404
A6: EU14 | B6: Italy | C6: 516850.89 | D6: 2416277.9 | E6: =D6/5 -> 483255.58 | F6: ='GHG & CO2 EMISSIONS'!E63 -> 521061.92 | G6: ='GHG & CO2 EMISSIONS'!F63 -> 522298.46 | H6: ='GHG & CO2 EMISSIONS'!G63 -> 521486.98 | I6: ='GHG & CO2 EMISSIONS'!H63 -> 514684.28 | J6: ='GHG & CO2 EMISSIONS'!I63 -> 508811.3 | K6: ='GHG & CO2 EMISSIONS'!J63 -> 535289.21 | L6: ='GHG & CO2 EMISSIONS'!K63 -> 530085.05 | M6: ='GHG & CO2 EMISSIONS'!L63 -> 537762.58 | ... AB6: ='GHG & CO2 EMISSIONS'!AA63 -> 488879.05 | AC6: -0.065 | AD6: =AVERAGE(X6:AB6) -> 518860.85 | AE6: =(AD6/C6)-1 -> 0.0038888681
A7: EU14 | B7: Spain | C7: 289773.21 | D7: 1666195.9 | E7: =D7/5 -> 333239.19 | F7: ='GHG & CO2 EMISSIONS'!E107 -> 287167.89 | G7: ='GHG & CO2 EMISSIONS'!F107 -> 295029.74 | H7: ='GHG & CO2 EMISSIONS'!G107 -> 304420.79 | I7: ='GHG & CO2 EMISSIONS'!H107 -> 294324.51 | J7: ='GHG & CO2 EMISSIONS'!I107 -> 310444.38 | K7: ='GHG & CO2 EMISSIONS'!J107 -> 326551.44 | L7: ='GHG & CO2 EMISSIONS'!K107 -> 318102.55 | M7: ='GHG & CO2 EMISSIONS'!L107 -> 332153.29 | ... AB7: ='GHG & CO2 EMISSIONS'!AA107 -> 347174.21 | AC7: 0.15 | AD7: =AVERAGE(X7:AB7) -> 366900.41 | AE7: =(AD7/C7)-1 -> 0.26616405
A8: EU14 | B8: Netherlands | C8: 213034.5 | D8: 1001262.1 | E8: =D8/5 -> 200252.43 | F8: ='GHG & CO2 EMISSIONS'!E83 -> 221843.64 | G8: ='GHG & CO2 EMISSIONS'!F83 -> 229669.32 | H8: ='GHG & CO2 EMISSIONS'!G83 -> 230109.3 | I8: ='GHG & CO2 EMISSIONS'!H83 -> 230444.4 | J8: ='GHG & CO2 EMISSIONS'!I83 -> 231159.08 | K8: ='GHG & CO2 EMISSIONS'!J83 -> 231245.67 | L8: ='GHG & CO2 EMISSIONS'!K83 -> 241569.03 | M8: ='GHG & CO2 EMISSIONS'!L83 -> 233154.37 | ... AB8: ='GHG & CO2 EMISSIONS'!AA83 -> 195479.23 | AC8: -0.06 | AD8: =AVERAGE(X8:AB8) -> 203822.81 | AE8: =(AD8/C8)-1 -> -0.043240338
A9: EU14 | B9: Belgium | C9: 145728.76 | D9: 673995.53 | E9: =D9/5 -> 134799.11 | F9: ='GHG & CO2 EMISSIONS'!E11 -> 145849.07 | G9: ='GHG & CO2 EMISSIONS'!F11 -> 148583.67 | H9: ='GHG & CO2 EMISSIONS'!G11 -> 148081.78 | I9: ='GHG & CO2 EMISSIONS'!H11 -> 146900.46 | J9: ='GHG & CO2 EMISSIONS'!I11 -> 151448.74 | K9: ='GHG & CO2 EMISSIONS'!J11 -> 153582.79 | L9: ='GHG & CO2 EMISSIONS'!K11 -> 157230.45 | M9: ='GHG & CO2 EMISSIONS'!L11 -> 148822.76 | ... AB9: ='GHG & CO2 EMISSIONS'!AA11 -> 120467.91 | AC9: -0.075 | AD9: =AVERAGE(X9:AB9) -> 128542.02 | AE9: =(AD9/C9)-1 -> -0.1179365
A10: EU14 | B10: Greece | C10: 106987.17 | D10: 668669.81 | E10: =D10/5 -> 133733.96 | F10: ='GHG & CO2 EMISSIONS'!E51 -> 103985.69 | G10: ='GHG & CO2 EMISSIONS'!F51 -> 104006.32 | H10: ='GHG & CO2 EMISSIONS'!G51 -> 105287.68 | I10: ='GHG & CO2 EMISSIONS'!H51 -> 104828.03 | J10: ='GHG & CO2 EMISSIONS'!I51 -> 107457.62 | K10: ='GHG & CO2 EMISSIONS'!J51 -> 109581.14 | L10: ='GHG & CO2 EMISSIONS'!K51 -> 112615.89 | M10: ='GHG & CO2 EMISSIONS'!L51 -> 117470.44 | ... AB10: ='GHG & CO2 EMISSIONS'!AA51 -> 113007.78 | AC10: 0.25 | AD10: =AVERAGE(X10:AB10) -> 121268.64 | AE10: =(AD10/C10)-1 -> 0.13348772
A11: EU14 | B11: Portugal | C11: 60147.642 | D11: 381937.53 | E11: =D11/5 -> 76387.505 | F11: ='GHG & CO2 EMISSIONS'!E91 -> 58857.193 | G11: ='GHG & CO2 EMISSIONS'!F91 -> 60797.334 | H11: ='GHG & CO2 EMISSIONS'!G91 -> 64590.689 | I11: ='GHG & CO2 EMISSIONS'!H91 -> 63026.476 | J11: ='GHG & CO2 EMISSIONS'!I91 -> 63940.678 | K11: ='GHG & CO2 EMISSIONS'!J91 -> 68653.009 | L11: ='GHG & CO2 EMISSIONS'!K91 -> 66431.628 | M11: ='GHG & CO2 EMISSIONS'!L91 -> 69673.852 | ... AB11: ='GHG & CO2 EMISSIONS'!AA91 -> 65337.813 | AC11: 0.27 | AD11: =AVERAGE(X11:AB11) -> 70181.645 | AE11: =(AD11/C11)-1 -> 0.16682288
A12: EU14 | B12: Sweden | C12: 72151.646 | D12: 375188.56 | E12: =D12/5 -> 75037.712 | F12: ='GHG & CO2 EMISSIONS'!E111 -> 71263.21 | G12: ='GHG & CO2 EMISSIONS'!F111 -> 71376.298 | H12: ='GHG & CO2 EMISSIONS'!G111 -> 71030.167 | I12: ='GHG & CO2 EMISSIONS'!H111 -> 71244.675 | J12: ='GHG & CO2 EMISSIONS'!I111 -> 73718.191 | K12: ='GHG & CO2 EMISSIONS'!J111 -> 73101.109 | L12: ='GHG & CO2 EMISSIONS'!K111 -> 77005.38 | M12: ='GHG & CO2 EMISSIONS'!L111 -> 72110.876 | ... AB12: ='GHG & CO2 EMISSIONS'!AA111 -> 56899.5 | AC12: 0.04 | AD12: =AVERAGE(X12:AB12) -> 60287.423 | AE12: =(AD12/C12)-1 -> -0.16443455
A13: EU14 | B13: Finland | C13: 71003.509 | D13: 355017.54 | E13: =D13/5 -> 71003.509 | F13: ='GHG & CO2 EMISSIONS'!E39 -> 71165.925 | G13: ='GHG & CO2 EMISSIONS'!F39 -> 69092.868 | H13: ='GHG & CO2 EMISSIONS'!G39 -> 67721.271 | I13: ='GHG & CO2 EMISSIONS'!H39 -> 69936.172 | J13: ='GHG & CO2 EMISSIONS'!I39 -> 75505.773 | K13: ='GHG & CO2 EMISSIONS'!J39 -> 71758.493 | L13: ='GHG & CO2 EMISSIONS'!K39 -> 77763.643 | M13: ='GHG & CO2 EMISSIONS'!L39 -> 76423.372 | ... AB13: ='GHG & CO2 EMISSIONS'!AA39 -> 62114.798 | AC13: 0 | AD13: =AVERAGE(X13:AB13) -> 68781.469 | AE13: =(AD13/C13)-1 -> -0.031294794
A14: EU14 | B14: Austria | C14: 79049.657 | D14: 343866.01 | E14: =D14/5 -> 68773.202 | F14: ='GHG & CO2 EMISSIONS'!E7 -> 79082.673 | G14: ='GHG & CO2 EMISSIONS'!F7 -> 82746.099 | H14: ='GHG & CO2 EMISSIONS'!G7 -> 76176.876 | I14: ='GHG & CO2 EMISSIONS'!H7 -> 76550.864 | J14: ='GHG & CO2 EMISSIONS'!I7 -> 76758.521 | K14: ='GHG & CO2 EMISSIONS'!J7 -> 79985.74 | L14: ='GHG & CO2 EMISSIONS'!K7 -> 83145.349 | M14: ='GHG & CO2 EMISSIONS'!L7 -> 82752.333 | ... AB14: ='GHG & CO2 EMISSIONS'!AA7 -> 79889.009 | AC14: -0.13 | AD14: =AVERAGE(X14:AB14) -> 82870.568 | AE14: =(AD14/C14)-1 -> 0.04833558
A15: EU14 | B15: Ireland | C15: 55607.836 | D15: 314184.27 | E15: =D15/5 -> 62836.854 | F15: ='GHG & CO2 EMISSIONS'!E59 -> 55231.48 | G15: ='GHG & CO2 EMISSIONS'!F59 -> 56154.194 | H15: ='GHG & CO2 EMISSIONS'!G59 -> 56199.408 | I15: ='GHG & CO2 EMISSIONS'!H59 -> 56807.499 | J15: ='GHG & CO2 EMISSIONS'!I59 -> 58216.827 | K15: ='GHG & CO2 EMISSIONS'!J59 -> 59705.977 | L15: ='GHG & CO2 EMISSIONS'!K59 -> 61869.754 | M15: ='GHG & CO2 EMISSIONS'!L59 -> 63306.263 | ... AB15: ='GHG & CO2 EMISSIONS'!AA59 -> 59668.461 | AC15: 0.13 | AD15: =AVERAGE(X15:AB15) -> 62659.854 | AE15: =(AD15/C15)-1 -> 0.12681699
A16: EU14 | B16: Denmark | C16: 69978 | D16: 276838.96 | E16: =D16/5 -> 55367.791 | F16: ='GHG & CO2 EMISSIONS'!E31 -> 70388.1 | G16: ='GHG & CO2 EMISSIONS'!F31 -> 81068.884 | H16: ='GHG & CO2 EMISSIONS'!G31 -> 75197.426 | I16: ='GHG & CO2 EMISSIONS'!H31 -> 77548.913 | J16: ='GHG & CO2 EMISSIONS'!I31 -> 81509.518 | K16: ='GHG & CO2 EMISSIONS'!J31 -> 78647.254 | L16: ='GHG & CO2 EMISSIONS'!K31 -> 91731.139 | M16: ='GHG & CO2 EMISSIONS'!L31 -> 82216.861 | ... AB16: ='GHG & CO2 EMISSIONS'!AA31 -> 54416.175 | AC16: -0.21 | AD16: =AVERAGE(X16:AB16) -> 61617.941 | AE16: =(AD16/C16)-1 -> -0.11946696
A17: EU14 | B17: Luxembourg | C17: 13167.499 | D17: 47402.996 | E17: =D17/5 -> 9480.5992 | F17: ='GHG & CO2 EMISSIONS'!E75 -> 12726.714 | G17: ='GHG & CO2 EMISSIONS'!F75 -> 13349.373 | H17: ='GHG & CO2 EMISSIONS'!G75 -> 13114.48 | I17: ='GHG & CO2 EMISSIONS'!H75 -> 13278.362 | J17: ='GHG & CO2 EMISSIONS'!I75 -> 12433.463 | K17: ='GHG & CO2 EMISSIONS'!J75 -> 10062.474 | L17: ='GHG & CO2 EMISSIONS'!K75 -> 10123.897 | M17: ='GHG & CO2 EMISSIONS'!L75 -> 9483.2283 | ... AB17: ='GHG & CO2 EMISSIONS'!AA75 -> 11803.372 | AC17: -0.28 | AD17: =AVERAGE(X17:AB17) -> 11943.114 | AE17: =(AD17/C17)-1 -> -0.092985354
A18: EU27 | B18: Cyprus | C18: N/A | D18: N/A | E18: N/A | F18: ='GHG & CO2 EMISSIONS'!E23 -> 5570.3489 | G18: ='GHG & CO2 EMISSIONS'!F23 -> 6074.8994 | H18: ='GHG & CO2 EMISSIONS'!G23 -> 6511.3843 | I18: ='GHG & CO2 EMISSIONS'!H23 -> 6798.5807 | J18: ='GHG & CO2 EMISSIONS'!I23 -> 7055.1086 | K18: ='GHG & CO2 EMISSIONS'!J23 -> 6970.5207 | L18: ='GHG & CO2 EMISSIONS'!K23 -> 7343.524 | M18: ='GHG & CO2 EMISSIONS'!L23 -> 7437.6235 | ... AB18: ='GHG & CO2 EMISSIONS'!AA23 -> 8628.5145 | AC18: N/A | AD18: =AVERAGE(X18:AB18) -> 9415.7029 | AE18: N/A
A19: EU27 | B19: Malta | C19: N/A | D19: N/A | E19: N/A | F19: ='GHG & CO2 EMISSIONS'!E79 -> 2626.1392 | G19: ='GHG & CO2 EMISSIONS'!F79 -> 2479.8521 | H19: ='GHG & CO2 EMISSIONS'!G79 -> 2512.8272 | I19: ='GHG & CO2 EMISSIONS'!H79 -> 3115.5736 | J19: ='GHG & CO2 EMISSIONS'!I79 -> 2893.6714 | K19: ='GHG & CO2 EMISSIONS'!J79 -> 2690.9395 | L19: ='GHG & CO2 EMISSIONS'!K79 -> 2781.5348 | M19: ='GHG & CO2 EMISSIONS'!L79 -> 2813.1701 | ... AB19: ='GHG & CO2 EMISSIONS'!AA79 -> 3142.7237 | AC19: N/A | AD19: =AVERAGE(X19:AB19) -> 3005.6471 | AE19: N/A
A20: EIT/EU27 | B20: Poland | C20: 563442.77 | D20: 2648181 | E20: =D20/5 -> 529636.21 | F20: ='GHG & CO2 EMISSIONS'!E87 -> 475466.59 | G20: ='GHG & CO2 EMISSIONS'!F87 -> 463378.49 | H20: ='GHG & CO2 EMISSIONS'!G87 -> 450631.5 | I20: ='GHG & CO2 EMISSIONS'!H87 -> 450220.13 | J20: ='GHG & CO2 EMISSIONS'!I87 -> 444563.48 | K20: ='GHG & CO2 EMISSIONS'!J87 -> 446357.37 | L20: ='GHG & CO2 EMISSIONS'!K87 -> 460100.68 | M20: ='GHG & CO2 EMISSIONS'!L87 -> 449935.6 | ... AB20: ='GHG & CO2 EMISSIONS'!AA87 -> 397501.77 | AC20: -0.06 | AD20: =AVERAGE(X20:AB20) -> 401356.26 | AE20: =(AD20/C20)-1 -> -0.28767165
A21: EIT/EU27 | B21: Romania | C21: 278225.02 | D21: 1279835.1 | E21: =D21/5 -> 255967.02 | F21: ='GHG & CO2 EMISSIONS'!E95 -> 256659.65 | G21: ='GHG & CO2 EMISSIONS'!F95 -> 210173.14 | H21: ='GHG & CO2 EMISSIONS'!G95 -> 194637.08 | I21: ='GHG & CO2 EMISSIONS'!H95 -> 184045.93 | J21: ='GHG & CO2 EMISSIONS'!I95 -> 181511.12 | K21: ='GHG & CO2 EMISSIONS'!J95 -> 188442.64 | L21: ='GHG & CO2 EMISSIONS'!K95 -> 191446.9 | M21: ='GHG & CO2 EMISSIONS'!L95 -> 184875.62 | ... AB21: ='GHG & CO2 EMISSIONS'!AA95 -> 129285.05 | AC21: -0.08 | AD21: =AVERAGE(X21:AB21) -> 133680.36 | AE21: =(AD21/C21)-1 -> -0.51952431
A22: EIT/EU27 | B22: Czech Republic | C22: 194248.22 | D22: 893541.8 | E22: =D22/5 -> 178708.36 | F22: ='GHG & CO2 EMISSIONS'!E27 -> 199386.71 | G22: ='GHG & CO2 EMISSIONS'!F27 -> 180862.33 | H22: ='GHG & CO2 EMISSIONS'!G27 -> 174988.44 | I22: ='GHG & CO2 EMISSIONS'!H27 -> 168156.55 | J22: ='GHG & CO2 EMISSIONS'!I27 -> 159400.88 | K22: ='GHG & CO2 EMISSIONS'!J27 -> 158415.84 | L22: ='GHG & CO2 EMISSIONS'!K27 -> 161630.92 | M22: ='GHG & CO2 EMISSIONS'!L27 -> 157199.21 | ... AB22: ='GHG & CO2 EMISSIONS'!AA27 -> 135193.43 | AC22: -0.08 | AD22: =AVERAGE(X22:AB22) -> 139948.46 | AE22: =(AD22/C22)-1 -> -0.27953798
A23: EIT/EU27 | B23: Bulgaria | C23: 132618.66 | D23: 610045.83 | E23: =D23/5 -> 122009.17 | F23: ='GHG & CO2 EMISSIONS'!E15 -> 98800.788 | G23: ='GHG & CO2 EMISSIONS'!F15 -> 80943.322 | H23: ='GHG & CO2 EMISSIONS'!G15 -> 75410.631 | I23: ='GHG & CO2 EMISSIONS'!H15 -> 74721.423 | J23: ='GHG & CO2 EMISSIONS'!I15 -> 70653.014 | K23: ='GHG & CO2 EMISSIONS'!J15 -> 72207.971 | L23: ='GHG & CO2 EMISSIONS'!K15 -> 72647.461 | M23: ='GHG & CO2 EMISSIONS'!L15 -> 69433.501 | ... AB23: ='GHG & CO2 EMISSIONS'!AA15 -> 59673.445 | AC23: -0.08 | AD23: =AVERAGE(X23:AB23) -> 61222.924 | AE23: =(AD23/C23)-1 -> -0.53835362
A24: EIT/EU27 | B24: Hungary | C24: 115397.15 | D24: 542366.6 | E24: =D24/5 -> 108473.32 | F24: ='GHG & CO2 EMISSIONS'!E55 -> 95061.823 | G24: ='GHG & CO2 EMISSIONS'!F55 -> 88848.046 | H24: ='GHG & CO2 EMISSIONS'!G55 -> 78861.161 | I24: ='GHG & CO2 EMISSIONS'!H55 -> 79352.053 | J24: ='GHG & CO2 EMISSIONS'!I55 -> 78871.162 | K24: ='GHG & CO2 EMISSIONS'!J55 -> 77669.517 | L24: ='GHG & CO2 EMISSIONS'!K55 -> 79916.274 | M24: ='GHG & CO2 EMISSIONS'!L55 -> 78499.438 | ... AB24: ='GHG & CO2 EMISSIONS'!AA55 -> 61510.854 | AC24: -0.06 | AD24: =AVERAGE(X24:AB24) -> 66142.923 | AE24: =(AD24/C24)-1 -> -0.42682359
A25: EIT/EU27 | B25: Slovakia | C25: 72050.764 | D25: 331433.52 | E25: =D25/5 -> 66286.703 | F25: ='GHG & CO2 EMISSIONS'!E99 -> 73367.554 | G25: ='GHG & CO2 EMISSIONS'!F99 -> 64113.275 | H25: ='GHG & CO2 EMISSIONS'!G99 -> 58682.586 | I25: ='GHG & CO2 EMISSIONS'!H99 -> 55098.133 | J25: ='GHG & CO2 EMISSIONS'!I99 -> 52582.406 | K25: ='GHG & CO2 EMISSIONS'!J99 -> 53097.986 | L25: ='GHG & CO2 EMISSIONS'!K99 -> 52952.359 | M25: ='GHG & CO2 EMISSIONS'!L99 -> 52747.073 | ... AB25: ='GHG & CO2 EMISSIONS'!AA99 -> 42396.044 | AC25: -0.08 | AD25: =AVERAGE(X25:AB25) -> 45476.864 | AE25: =(AD25/C25)-1 -> -0.3688219
A26: EIT/EU27 | B26: Lithuania | C26: 49414.386 | D26: 227306.18 | E26: =D26/5 -> 45461.235 | F26: ='GHG & CO2 EMISSIONS'!E71 -> 48020.05 | G26: ='GHG & CO2 EMISSIONS'!F71 -> 49979.147 | H26: ='GHG & CO2 EMISSIONS'!G71 -> 30947.151 | I26: ='GHG & CO2 EMISSIONS'!H71 -> 24825.129 | J26: ='GHG & CO2 EMISSIONS'!I71 -> 23435.231 | K26: ='GHG & CO2 EMISSIONS'!J71 -> 22401.485 | L26: ='GHG & CO2 EMISSIONS'!K71 -> 23371.656 | M26: ='GHG & CO2 EMISSIONS'!L71 -> 22918.838 | ... AB26: ='GHG & CO2 EMISSIONS'!AA71 -> 20971.422 | AC26: -0.08 | AD26: =AVERAGE(X26:AB26) -> 21207.182 | AE26: =(AD26/C26)-1 -> -0.57082979
A27: EIT/EU27 | B27: Estonia | C27: 42622.312 | D27: 196062.64 | E27: =D27/5 -> 39212.527 | F27: ='GHG & CO2 EMISSIONS'!E35 -> 40273.576 | G27: ='GHG & CO2 EMISSIONS'!F35 -> 37398.494 | H27: ='GHG & CO2 EMISSIONS'!G35 -> 27212.186 | I27: ='GHG & CO2 EMISSIONS'!H35 -> 21747.878 | J27: ='GHG & CO2 EMISSIONS'!I35 -> 22220.199 | K27: ='GHG & CO2 EMISSIONS'!J35 -> 20057.12 | L27: ='GHG & CO2 EMISSIONS'!K35 -> 20998.018 | M27: ='GHG & CO2 EMISSIONS'!L35 -> 20708.904 | ... AB27: ='GHG & CO2 EMISSIONS'!AA35 -> 19941.947 | AC27: -0.08 | AD27: =AVERAGE(X27:AB27) -> 19703.391 | AE27: =(AD27/C27)-1 -> -0.53772122
A28: EIT/EU27 | B28: Latvia | C28: 25909.159 | D28: 119182.13 | E28: =D28/5 -> 23836.426 | F28: ='GHG & CO2 EMISSIONS'!E67 -> 26020.479 | G28: ='GHG & CO2 EMISSIONS'!F67 -> 24130.488 | H28: ='GHG & CO2 EMISSIONS'!G67 -> 19359.739 | I28: ='GHG & CO2 EMISSIONS'!H67 -> 15903.167 | J28: ='GHG & CO2 EMISSIONS'!I67 -> 13956.169 | K28: ='GHG & CO2 EMISSIONS'!J67 -> 12587.644 | L28: ='GHG & CO2 EMISSIONS'!K67 -> 12637.113 | M28: ='GHG & CO2 EMISSIONS'!L67 -> 12078.166 | ... AB28: ='GHG & CO2 EMISSIONS'!AA67 -> 10894.224 | AC28: -0.08 | AD28: =AVERAGE(X28:AB28) -> 11221.571 | AE28: =(AD28/C28)-1 -> -0.56688787
A29: EIT/EU27 | B29: Slovenia | C29: 20354.042 | D29: 93628.593 | E29: =D29/5 -> 18725.719 | F29: ='GHG & CO2 EMISSIONS'!E103 -> 18802.399 | G29: ='GHG & CO2 EMISSIONS'!F103 -> 17446.782 | H29: ='GHG & CO2 EMISSIONS'!G103 -> 17434.778 | I29: ='GHG & CO2 EMISSIONS'!H103 -> 17675.709 | J29: ='GHG & CO2 EMISSIONS'!I103 -> 18080.754 | K29: ='GHG & CO2 EMISSIONS'!J103 -> 18857.184 | L29: ='GHG & CO2 EMISSIONS'!K103 -> 19445.63 | M29: ='GHG & CO2 EMISSIONS'!L103 -> 19986.371 | ... AB29: ='GHG & CO2 EMISSIONS'!AA103 -> 19038.515 | AC29: -0.08 | AD29: =AVERAGE(X29:AB29) -> 19927.596 | AE29: =(AD29/C29)-1 -> -0.020951413
A30: EIT | B30: Russia | C30: 3323419.1 | D30: 16617095 | E30: =D30/5 -> 3323419.1 | F30: ='GHG & CO2 EMISSIONS'!E167 -> 3142797.5 | G30: ='GHG & CO2 EMISSIONS'!F167 -> 2987852.8 | H30: ='GHG & CO2 EMISSIONS'!G167 -> 2512071.5 | I30: ='GHG & CO2 EMISSIONS'!H167 -> 2378462.7 | J30: ='GHG & CO2 EMISSIONS'!I167 -> 2117939.4 | K30: ='GHG & CO2 EMISSIONS'!J167 -> 2065422.6 | L30: ='GHG & CO2 EMISSIONS'!K167 -> 2014841.2 | M30: ='GHG & CO2 EMISSIONS'!L167 -> 1895331.9 | ... AB30: ='GHG & CO2 EMISSIONS'!AA167 -> 2071103.3 | AC30: 0 | AD30: =AVERAGE(X30:AB30) -> 2011594.6 | AE30: =(AD30/C30)-1 -> -0.39472134
A31: EIT | B31: Ukraine | C31: 920836.93 | D31: 4604184.7 | E31: =D31/5 -> 920836.93 | F31: ='GHG & CO2 EMISSIONS'!E151 -> 962527.75 | G31: ='GHG & CO2 EMISSIONS'!F151 -> 875728.92 | H31: ='GHG & CO2 EMISSIONS'!G151 -> 819946.97 | I31: ='GHG & CO2 EMISSIONS'!H151 -> 728907.09 | J31: ='GHG & CO2 EMISSIONS'!I151 -> 622241.88 | K31: ='GHG & CO2 EMISSIONS'!J151 -> 578197.7 | L31: ='GHG & CO2 EMISSIONS'!K151 -> 531404.53 | M31: ='GHG & CO2 EMISSIONS'!L151 -> 513839.97 | ... AB31: ='GHG & CO2 EMISSIONS'!AA151 -> 425553.61 | AC31: 0 | AD31: =AVERAGE(X31:AB31) -> 427847.01 | AE31: =(AD31/C31)-1 -> -0.53537158
A32: EIT | B32: Croatia | C32: 31321.79 | D32: 148778.5 | E32: =D32/5 -> 29755.701 | F32: ='GHG & CO2 EMISSIONS'!E19 -> 31546.32 | G32: ='GHG & CO2 EMISSIONS'!F19 -> 25021.258 | H32: ='GHG & CO2 EMISSIONS'!G19 -> 23134.505 | I32: ='GHG & CO2 EMISSIONS'!H19 -> 23122.502 | J32: ='GHG & CO2 EMISSIONS'!I19 -> 22206.748 | K32: ='GHG & CO2 EMISSIONS'!J19 -> 22875.232 | L32: ='GHG & CO2 EMISSIONS'!K19 -> 23366.34 | M32: ='GHG & CO2 EMISSIONS'!L19 -> 24748.203 | ... AB32: ='GHG & CO2 EMISSIONS'!AA19 -> 26265.917 | AC32: -0.05 | AD32: =AVERAGE(X32:AB32) -> 28412.663 | AE32: =(AD32/C32)-1 -> -0.092878693
A33: Other | B33: Japan | C33: 1261331.4 | D33: 5928257.7 | E33: =D33/5 -> 1185651.5 | F33: ='GHG & CO2 EMISSIONS'!E159 -> 1269430.6 | G33: ='GHG & CO2 EMISSIONS'!F159 -> 1283622.9 | H33: ='GHG & CO2 EMISSIONS'!G159 -> 1295413 | I33: ='GHG & CO2 EMISSIONS'!H159 -> 1290874 | J33: ='GHG & CO2 EMISSIONS'!I159 -> 1351092 | K33: ='GHG & CO2 EMISSIONS'!J159 -> 1371412.5 | L33: ='GHG & CO2 EMISSIONS'!K159 -> 1384052.4 | M33: ='GHG & CO2 EMISSIONS'!L159 -> 1375902.7 | ... AB33: ='GHG & CO2 EMISSIONS'!AA159 -> 1393327.2 | AC33: -0.06 | AD33: =AVERAGE(X33:AB33) -> 1322013.7 | AE33: =(AD33/C33)-1 -> 0.048109681
A34: Other | B34: United Kingdom | C34: 779904.14 | D34: 3412080.6 | E34: =D34/5 -> 682416.13 | F34: ='GHG & CO2 EMISSIONS'!E155 -> 805610.85 | G34: ='GHG & CO2 EMISSIONS'!F155 -> 814428.74 | H34: ='GHG & CO2 EMISSIONS'!G155 -> 794096.75 | I34: ='GHG & CO2 EMISSIONS'!H155 -> 775060.91 | J34: ='GHG & CO2 EMISSIONS'!I155 -> 762886.95 | K34: ='GHG & CO2 EMISSIONS'!J155 -> 756780.05 | L34: ='GHG & CO2 EMISSIONS'!K155 -> 777414.37 | M34: ='GHG & CO2 EMISSIONS'!L155 -> 753198.85 | ... AB34: ='GHG & CO2 EMISSIONS'!AA155 -> 585241.18 | AC34: -0.125 | AD34: =AVERAGE(X34:AB34) -> 605494.33 | AE34: =(AD34/C34)-1 -> -0.22362981
A35: Other | B35: Canada | C35: 593998.46 | D35: 2791792.8 | E35: =D35/5 -> 558358.55 | F35: ='GHG & CO2 EMISSIONS'!E171 -> 607748.76 | G35: ='GHG & CO2 EMISSIONS'!F171 -> 603138.23 | H35: ='GHG & CO2 EMISSIONS'!G171 -> 621534.93 | I35: ='GHG & CO2 EMISSIONS'!H171 -> 626611.05 | J35: ='GHG & CO2 EMISSIONS'!I171 -> 649033.64 | K35: ='GHG & CO2 EMISSIONS'!J171 -> 667914.71 | L35: ='GHG & CO2 EMISSIONS'!K171 -> 689261.89 | M35: ='GHG & CO2 EMISSIONS'!L171 -> 705539.09 | ... AB35: ='GHG & CO2 EMISSIONS'!AA171 -> 743856.56 | AC35: -0.06 | AD35: =AVERAGE(X35:AB35) -> 737278.41 | AE35: =(AD35/C35)-1 -> 0.24121266
A36: Other | B36: Australia | C36: 547699.84 | D36: 2957579.1 | E36: =D36/5 -> 591515.83 | F36: ='GHG & CO2 EMISSIONS'!E115 -> 437120 | G36: ='GHG & CO2 EMISSIONS'!F115 -> 437222 | H36: ='GHG & CO2 EMISSIONS'!G115 -> 441027 | I36: ='GHG & CO2 EMISSIONS'!H115 -> 441346 | J36: ='GHG & CO2 EMISSIONS'!I115 -> 441583 | K36: ='GHG & CO2 EMISSIONS'!J115 -> 450276 | L36: ='GHG & CO2 EMISSIONS'!K115 -> 456436 | M36: ='GHG & CO2 EMISSIONS'!L115 -> 468506 | ... AB36: ='GHG & CO2 EMISSIONS'!AA115 -> 550596 | AC36: 0.08 | AD36: =AVERAGE(X36:AB36) -> 548695.2 | AE36: =(AD36/C36)-1 -> 0.0018173434
A37: Other | B37: New Zealand | C37: 61912.947 | D37: 309564.73 | E37: =D37/5 -> 61912.947 | F37: ='GHG & CO2 EMISSIONS'!E163 -> 68958.182 | G37: ='GHG & CO2 EMISSIONS'!F163 -> 69918.613 | H37: ='GHG & CO2 EMISSIONS'!G163 -> 71163.043 | I37: ='GHG & CO2 EMISSIONS'!H163 -> 71017.985 | J37: ='GHG & CO2 EMISSIONS'!I163 -> 72398.449 | K37: ='GHG & CO2 EMISSIONS'!J163 -> 72988.347 | L37: ='GHG & CO2 EMISSIONS'!K163 -> 75526.573 | M37: ='GHG & CO2 EMISSIONS'!L163 -> 78163.571 | ... AB37: ='GHG & CO2 EMISSIONS'!AA163 -> 84065.667 | AC37: 0 | AD37: =AVERAGE(X37:AB37) -> 82713.851 | AE37: =(AD37/C37)-1 -> 0.33597019
A38: Other | B38: Switzerland | C38: 52790.957 | D38: 242838.4 | E38: =D38/5 -> 48567.68 | F38: ='GHG & CO2 EMISSIONS'!E143 -> 54665.543 | G38: ='GHG & CO2 EMISSIONS'!F143 -> 56538.209 | H38: ='GHG & CO2 EMISSIONS'!G143 -> 56272.972 | I38: ='GHG & CO2 EMISSIONS'!H143 -> 53679.345 | J38: ='GHG & CO2 EMISSIONS'!I143 -> 52622.104 | K38: ='GHG & CO2 EMISSIONS'!J143 -> 53511.064 | L38: ='GHG & CO2 EMISSIONS'!K143 -> 54173.138 | M38: ='GHG & CO2 EMISSIONS'!L143 -> 52971.46 | ... AB38: ='GHG & CO2 EMISSIONS'!AA143 -> 52375.113 | AC38: -0.08 | AD38: =AVERAGE(X38:AB38) -> 53441.781 | AE38: =(AD38/C38)-1 -> 0.012328318
A39: Other | B39: Norway | C39: 49619.168 | D39: 250576.8 | E39: =D39/5 -> 50115.359 | F39: ='GHG & CO2 EMISSIONS'!E139 -> 50796.769 | G39: ='GHG & CO2 EMISSIONS'!F139 -> 48400.868 | H39: ='GHG & CO2 EMISSIONS'!G139 -> 46770.379 | I39: ='GHG & CO2 EMISSIONS'!H139 -> 48639.02 | J39: ='GHG & CO2 EMISSIONS'!I139 -> 50545.045 | K39: ='GHG & CO2 EMISSIONS'!J139 -> 50904.268 | L39: ='GHG & CO2 EMISSIONS'!K139 -> 53786.903 | M39: ='GHG & CO2 EMISSIONS'!L139 -> 53750.972 | ... AB39: ='GHG & CO2 EMISSIONS'!AA139 -> 53020.557 | AC39: 0.01 | AD39: =AVERAGE(X39:AB39) -> 53619.97 | AE39: =(AD39/C39)-1 -> 0.08063017
A40: Other | B40: Iceland | C40: 3367.9722 | D40: 18523.847 | E40: =D40/5 -> 3704.7694 | F40: ='GHG & CO2 EMISSIONS'!E123 -> 3644.8859 | G40: ='GHG & CO2 EMISSIONS'!F123 -> 3433.5371 | H40: ='GHG & CO2 EMISSIONS'!G123 -> 3363.3465 | I40: ='GHG & CO2 EMISSIONS'!H123 -> 3446.5113 | J40: ='GHG & CO2 EMISSIONS'!I123 -> 3376.3893 | K40: ='GHG & CO2 EMISSIONS'!J123 -> 3503.9526 | L40: ='GHG & CO2 EMISSIONS'!K123 -> 3558.703 | M40: ='GHG & CO2 EMISSIONS'!L123 -> 3715.6564 | ... AB40: ='GHG & CO2 EMISSIONS'!AA123 -> 4648.787 | AC40: 0.1 | AD40: =AVERAGE(X40:AB40) -> 4881.0756 | AE40: =(AD40/C40)-1 -> 0.44926244
...

Sheet Working sheet
A1: Working Sheet
A2: INSTRUCTIONS
A3: *** This sheet is to remain hidden. It copies the values from the main sheet in order to sort them out from smallest to highest values.
A4: *** This sorting out facilitates data visualisation in the Analytics sheet.
A5: *** When updating the database, use the template at the bottom to add all the data in the original order, before sorting them out again.
A6: *** For annual emissions, sort out values based on the latest reported year (or the prior year if one country has a year marked N/A)
A9: Change from base to latest reported year
A10: Ukraine | B10: ='GHG & CO2 EMISSIONS'!AN151 -> -0.66341626
A11: United Kingdom | B11: ='GHG & CO2 EMISSIONS'!AN155 -> -0.49162603
A12: Belarus | B12: ='GHG & CO2 EMISSIONS'!AN119 -> -0.39488485
A13: Russia | B13: ='GHG & CO2 EMISSIONS'!AN167 -> -0.35025186
A14: Switzerland | B14: ='GHG & CO2 EMISSIONS'!AN143 -> -0.24017704
A15: European Union (excl. UK) | B15: ='GHG & CO2 EMISSIONS'!AN3 -> -0.30732469
A16: Monaco | B16: ='GHG & CO2 EMISSIONS'!AN135 -> -0.34457578
A17: Liechtenstein | B17: ='GHG & CO2 EMISSIONS'!AN131 -> -0.27724473
A18: United States of America | B18: ='GHG & CO2 EMISSIONS'!AN175 -> -0.15363356
A19: Japan | B19: ='GHG & CO2 EMISSIONS'!AN159 -> -0.17734996
A20: Norway | B20: ='GHG & CO2 EMISSIONS'!AN139 -> -0.040196116
A21: Canada | B21: ='GHG & CO2 EMISSIONS'!AN171 -> -0.070552413
A22: Kazakhstan | B22: ='GHG & CO2 EMISSIONS'!AN127 -> 0.014659477
A23: Australia | B23: ='GHG & CO2 EMISSIONS'!AN115 -> 0.041046812
A24: New Zealand | B24: ='GHG & CO2 EMISSIONS'!AN163 -> 0.13685369
A25: Iceland | B25: ='GHG & CO2 EMISSIONS'!AN123 -> 0.28015005
A26: Turkey | B26: ='GHG & CO2 EMISSIONS'!AN147 -> 1.4485342
A29: GHG emissions without LULUCF (1,000 tCO2)
B30: 1990 | C30: 1991 | D30: 1992 | E30: 1993 | F30: 1994 | G30: 1995 | H30: 1996 | I30: 1997 | J30: 1998 | K30: 1999 | L30: 2000 | M30: 2001 | N30: 2002 | O30: 2003 | P30: 2004 | Q30: 2005 | R30: 2006 | S30: 2007 | T30: 2008 | U30: 2009 | V30: 2010 | W30: 2011 | X30: 2012 | Y30: 2013 | Z30: 2014 | AA30: 2015 | AB30: 2016 | AC30: 2017 | AD30: 2018 | AE30: 2019 | AF30: 2020 | AG30: 2021 | AH30: 2022
A31: Monaco | B31: ='GHG & CO2 EMISSIONS'!E135 -> 101.51215 | C31: ='GHG & CO2 EMISSIONS'!F135 -> 102.41396 | D31: ='GHG & CO2 EMISSIONS'!G135 -> 107.98423 | E31: ='GHG & CO2 EMISSIONS'!H135 -> 106.92218 | F31: ='GHG & CO2 EMISSIONS'!I135 -> 107.53616 | G31: ='GHG & CO2 EMISSIONS'!J135 -> 104.18725 | H31: ='GHG & CO2 EMISSIONS'!K135 -> 107.86782 | I31: ='GHG & CO2 EMISSIONS'!L135 -> 106.25857 | ... AH31: ='GHG & CO2 EMISSIONS'!AK135 -> 66.533519
A32: Liechtenstein | B32: ='GHG & CO2 EMISSIONS'!E131 -> 229.01311 | C32: ='GHG & CO2 EMISSIONS'!F131 -> 236.54326 | D32: ='GHG & CO2 EMISSIONS'!G131 -> 236.68938 | E32: ='GHG & CO2 EMISSIONS'!H131 -> 243.72603 | F32: ='GHG & CO2 EMISSIONS'!I131 -> 230.05527 | G32: ='GHG & CO2 EMISSIONS'!J131 -> 233.78978 | H32: ='GHG & CO2 EMISSIONS'!K131 -> 236.11183 | I32: ='GHG & CO2 EMISSIONS'!L131 -> 248.61113 | ... AH32: ='GHG & CO2 EMISSIONS'!AK131 -> 165.52043
